{
    "containers": {
        "cna": {
            "affected": [
                {
                    "product": "tensorflow",
                    "vendor": "tensorflow",
                    "versions": [
                        {
                            "status": "affected",
                            "version": "< 2.1.4"
                        },
                        {
                            "status": "affected",
                            "version": ">= 2.2.0, < 2.2.3"
                        },
                        {
                            "status": "affected",
                            "version": ">= 2.3.0, < 2.3.3"
                        },
                        {
                            "status": "affected",
                            "version": ">= 2.4.0, < 2.4.2"
                        }
                    ]
                }
            ],
            "descriptions": [
                {
                    "lang": "en",
                    "value": "TensorFlow is an end-to-end open source platform for machine learning. An attacker can trigger a denial of service via a `CHECK` failure by passing an empty image to `tf.raw_ops.DrawBoundingBoxes`. This is because the implementation(https://github.com/tensorflow/tensorflow/blob/ea34a18dc3f5c8d80a40ccca1404f343b5d55f91/tensorflow/core/kernels/image/draw_bounding_box_op.cc#L148-L165) uses `CHECK_*` assertions instead of `OP_REQUIRES` to validate user controlled inputs. Whereas `OP_REQUIRES` allows returning an error condition back to the user, the `CHECK_*` macros result in a crash if the condition is false, similar to `assert`. In this case, `height` is 0 from the `images` input. This results in `max_box_row_clamp` being negative and the assertion being falsified, followed by aborting program execution. The fix will be included in TensorFlow 2.5.0. We will also cherrypick this commit on TensorFlow 2.4.2, TensorFlow 2.3.3, TensorFlow 2.2.3 and TensorFlow 2.1.4, as these are also affected and still in supported range."
                }
            ],
            "metrics": [
                {
                    "cvssV3_1": {
                        "attackComplexity": "HIGH",
                        "attackVector": "LOCAL",
                        "availabilityImpact": "LOW",
                        "baseScore": 2.5,
                        "baseSeverity": "LOW",
                        "confidentialityImpact": "NONE",
                        "integrityImpact": "NONE",
                        "privilegesRequired": "LOW",
                        "scope": "UNCHANGED",
                        "userInteraction": "NONE",
                        "vectorString": "CVSS:3.1/AV:L/AC:H/PR:L/UI:N/S:U/C:N/I:N/A:L",
                        "version": "3.1"
                    }
                }
            ],
            "problemTypes": [
                {
                    "descriptions": [
                        {
                            "cweId": "CWE-754",
                            "description": "CWE-754: Improper Check for Unusual or Exceptional Conditions",
                            "lang": "en",
                            "type": "CWE"
                        }
                    ]
                }
            ],
            "providerMetadata": {
                "dateUpdated": "2021-05-14T19:12:02",
                "orgId": "a0819718-46f1-4df5-94e2-005712e83aaa",
                "shortName": "GitHub_M"
            },
            "references": [
                {
                    "tags": [
                        "x_refsource_CONFIRM"
                    ],
                    "url": "https://github.com/tensorflow/tensorflow/security/advisories/GHSA-393f-2jr3-cp69"
                },
                {
                    "tags": [
                        "x_refsource_MISC"
                    ],
                    "url": "https://github.com/tensorflow/tensorflow/commit/b432a38fe0e1b4b904a6c222cbce794c39703e87"
                }
            ],
            "source": {
                "advisory": "GHSA-393f-2jr3-cp69",
                "discovery": "UNKNOWN"
            },
            "title": "CHECK-fail in DrawBoundingBoxes",
            "x_legacyV4Record": {
                "CVE_data_meta": {
                    "ASSIGNER": "security-advisories@github.com",
                    "ID": "CVE-2021-29533",
                    "STATE": "PUBLIC",
                    "TITLE": "CHECK-fail in DrawBoundingBoxes"
                },
                "affects": {
                    "vendor": {
                        "vendor_data": [
                            {
                                "product": {
                                    "product_data": [
                                        {
                                            "product_name": "tensorflow",
                                            "version": {
                                                "version_data": [
                                                    {
                                                        "version_value": "< 2.1.4"
                                                    },
                                                    {
                                                        "version_value": ">= 2.2.0, < 2.2.3"
                                                    },
                                                    {
                                                        "version_value": ">= 2.3.0, < 2.3.3"
                                                    },
                                                    {
                                                        "version_value": ">= 2.4.0, < 2.4.2"
                                                    }
                                                ]
                                            }
                                        }
                                    ]
                                },
                                "vendor_name": "tensorflow"
                            }
                        ]
                    }
                },
                "data_format": "MITRE",
                "data_type": "CVE",
                "data_version": "4.0",
                "description": {
                    "description_data": [
                        {
                            "lang": "eng",
                            "value": "TensorFlow is an end-to-end open source platform for machine learning. An attacker can trigger a denial of service via a `CHECK` failure by passing an empty image to `tf.raw_ops.DrawBoundingBoxes`. This is because the implementation(https://github.com/tensorflow/tensorflow/blob/ea34a18dc3f5c8d80a40ccca1404f343b5d55f91/tensorflow/core/kernels/image/draw_bounding_box_op.cc#L148-L165) uses `CHECK_*` assertions instead of `OP_REQUIRES` to validate user controlled inputs. Whereas `OP_REQUIRES` allows returning an error condition back to the user, the `CHECK_*` macros result in a crash if the condition is false, similar to `assert`. In this case, `height` is 0 from the `images` input. This results in `max_box_row_clamp` being negative and the assertion being falsified, followed by aborting program execution. The fix will be included in TensorFlow 2.5.0. We will also cherrypick this commit on TensorFlow 2.4.2, TensorFlow 2.3.3, TensorFlow 2.2.3 and TensorFlow 2.1.4, as these are also affected and still in supported range."
                        }
                    ]
                },
                "impact": {
                    "cvss": {
                        "attackComplexity": "HIGH",
                        "attackVector": "LOCAL",
                        "availabilityImpact": "LOW",
                        "baseScore": 2.5,
                        "baseSeverity": "LOW",
                        "confidentialityImpact": "NONE",
                        "integrityImpact": "NONE",
                        "privilegesRequired": "LOW",
                        "scope": "UNCHANGED",
                        "userInteraction": "NONE",
                        "vectorString": "CVSS:3.1/AV:L/AC:H/PR:L/UI:N/S:U/C:N/I:N/A:L",
                        "version": "3.1"
                    }
                },
                "problemtype": {
                    "problemtype_data": [
                        {
                            "description": [
                                {
                                    "lang": "eng",
                                    "value": "CWE-754: Improper Check for Unusual or Exceptional Conditions"
                                }
                            ]
                        }
                    ]
                },
                "references": {
                    "reference_data": [
                        {
                            "name": "https://github.com/tensorflow/tensorflow/security/advisories/GHSA-393f-2jr3-cp69",
                            "refsource": "CONFIRM",
                            "url": "https://github.com/tensorflow/tensorflow/security/advisories/GHSA-393f-2jr3-cp69"
                        },
                        {
                            "name": "https://github.com/tensorflow/tensorflow/commit/b432a38fe0e1b4b904a6c222cbce794c39703e87",
                            "refsource": "MISC",
                            "url": "https://github.com/tensorflow/tensorflow/commit/b432a38fe0e1b4b904a6c222cbce794c39703e87"
                        }
                    ]
                },
                "source": {
                    "advisory": "GHSA-393f-2jr3-cp69",
                    "discovery": "UNKNOWN"
                }
            }
        }
    },
    "cveMetadata": {
        "assignerOrgId": "a0819718-46f1-4df5-94e2-005712e83aaa",
        "assignerShortName": "GitHub_M",
        "cveId": "CVE-2021-29533",
        "datePublished": "2021-05-14T19:12:02",
        "dateReserved": "2021-03-30T00:00:00",
        "dateUpdated": "2021-05-14T19:12:02",
        "state": "PUBLISHED"
    },
    "dataType": "CVE_RECORD",
    "dataVersion": "5.0"
}