{
    "containers": {
        "cna": {
            "affected": [
                {
                    "product": "n/a",
                    "vendor": "n/a",
                    "versions": [
                        {
                            "status": "affected",
                            "version": "n/a"
                        }
                    ]
                }
            ],
            "descriptions": [
                {
                    "lang": "en",
                    "value": "before_upstream_connection in AuthPlugin in http/proxy/auth.py in proxy.py before 2.3.1 accepts incorrect Proxy-Authorization header data because of a boolean confusion (and versus or)."
                }
            ],
            "problemTypes": [
                {
                    "descriptions": [
                        {
                            "description": "n/a",
                            "lang": "en",
                            "type": "text"
                        }
                    ]
                }
            ],
            "providerMetadata": {
                "dateUpdated": "2021-01-11T05:00:49",
                "orgId": "8254265b-2729-46b6-b9e3-3dfca2d5bfca",
                "shortName": "mitre"
            },
            "references": [
                {
                    "tags": [
                        "x_refsource_MISC"
                    ],
                    "url": "https://cardaci.xyz/advisories/2021/01/10/proxy.py-2.3.0-broken-basic-authentication/"
                },
                {
                    "tags": [
                        "x_refsource_MISC"
                    ],
                    "url": "https://github.com/abhinavsingh/proxy.py/pull/482/commits/9b00093288237f5073c403f2c4f62acfdfa8ed46"
                },
                {
                    "tags": [
                        "x_refsource_MISC"
                    ],
                    "url": "https://pypi.org/project/proxy.py/2.3.1/#history"
                }
            ],
            "x_legacyV4Record": {
                "CVE_data_meta": {
                    "ASSIGNER": "cve@mitre.org",
                    "ID": "CVE-2021-3116",
                    "STATE": "PUBLIC"
                },
                "affects": {
                    "vendor": {
                        "vendor_data": [
                            {
                                "product": {
                                    "product_data": [
                                        {
                                            "product_name": "n/a",
                                            "version": {
                                                "version_data": [
                                                    {
                                                        "version_value": "n/a"
                                                    }
                                                ]
                                            }
                                        }
                                    ]
                                },
                                "vendor_name": "n/a"
                            }
                        ]
                    }
                },
                "data_format": "MITRE",
                "data_type": "CVE",
                "data_version": "4.0",
                "description": {
                    "description_data": [
                        {
                            "lang": "eng",
                            "value": "before_upstream_connection in AuthPlugin in http/proxy/auth.py in proxy.py before 2.3.1 accepts incorrect Proxy-Authorization header data because of a boolean confusion (and versus or)."
                        }
                    ]
                },
                "problemtype": {
                    "problemtype_data": [
                        {
                            "description": [
                                {
                                    "lang": "eng",
                                    "value": "n/a"
                                }
                            ]
                        }
                    ]
                },
                "references": {
                    "reference_data": [
                        {
                            "name": "https://cardaci.xyz/advisories/2021/01/10/proxy.py-2.3.0-broken-basic-authentication/",
                            "refsource": "MISC",
                            "url": "https://cardaci.xyz/advisories/2021/01/10/proxy.py-2.3.0-broken-basic-authentication/"
                        },
                        {
                            "name": "https://github.com/abhinavsingh/proxy.py/pull/482/commits/9b00093288237f5073c403f2c4f62acfdfa8ed46",
                            "refsource": "MISC",
                            "url": "https://github.com/abhinavsingh/proxy.py/pull/482/commits/9b00093288237f5073c403f2c4f62acfdfa8ed46"
                        },
                        {
                            "name": "https://pypi.org/project/proxy.py/2.3.1/#history",
                            "refsource": "MISC",
                            "url": "https://pypi.org/project/proxy.py/2.3.1/#history"
                        }
                    ]
                }
            }
        }
    },
    "cveMetadata": {
        "assignerOrgId": "8254265b-2729-46b6-b9e3-3dfca2d5bfca",
        "assignerShortName": "mitre",
        "cveId": "CVE-2021-3116",
        "datePublished": "2021-01-11T05:00:49",
        "dateReserved": "2021-01-11T00:00:00",
        "dateUpdated": "2021-01-11T05:00:49",
        "state": "PUBLISHED"
    },
    "dataType": "CVE_RECORD",
    "dataVersion": "5.0"
}