{
    "containers": {
        "cna": {
            "affected": [
                {
                    "product": "tensorflow",
                    "vendor": "tensorflow",
                    "versions": [
                        {
                            "status": "affected",
                            "version": ">= 2.7.0, < 2.8.0"
                        }
                    ]
                }
            ],
            "descriptions": [
                {
                    "lang": "en",
                    "value": "Tensorflow is an Open Source Machine Learning Framework. TensorFlow's type inference can cause a heap out of bounds read as the bounds checking is done in a `DCHECK` (which is a no-op during production). An attacker can control the `input_idx` variable such that `ix` would be larger than the number of values in `node_t.args`. The fix will be included in TensorFlow 2.8.0. This is the only affected version."
                }
            ],
            "metrics": [
                {
                    "cvssV3_1": {
                        "attackComplexity": "LOW",
                        "attackVector": "NETWORK",
                        "availabilityImpact": "HIGH",
                        "baseScore": 8.1,
                        "baseSeverity": "HIGH",
                        "confidentialityImpact": "HIGH",
                        "integrityImpact": "NONE",
                        "privilegesRequired": "LOW",
                        "scope": "UNCHANGED",
                        "userInteraction": "NONE",
                        "vectorString": "CVSS:3.1/AV:N/AC:L/PR:L/UI:N/S:U/C:H/I:N/A:H",
                        "version": "3.1"
                    }
                }
            ],
            "problemTypes": [
                {
                    "descriptions": [
                        {
                            "cweId": "CWE-125",
                            "description": "CWE-125: Out-of-bounds Read",
                            "lang": "en",
                            "type": "CWE"
                        }
                    ]
                }
            ],
            "providerMetadata": {
                "dateUpdated": "2022-02-04T22:32:14",
                "orgId": "a0819718-46f1-4df5-94e2-005712e83aaa",
                "shortName": "GitHub_M"
            },
            "references": [
                {
                    "tags": [
                        "x_refsource_CONFIRM"
                    ],
                    "url": "https://github.com/tensorflow/tensorflow/security/advisories/GHSA-vq36-27g6-p492"
                },
                {
                    "tags": [
                        "x_refsource_MISC"
                    ],
                    "url": "https://github.com/tensorflow/tensorflow/commit/c99d98cd189839dcf51aee94e7437b54b31f8abd"
                },
                {
                    "tags": [
                        "x_refsource_MISC"
                    ],
                    "url": "https://github.com/tensorflow/tensorflow/blob/274df9b02330b790aa8de1cee164b70f72b9b244/tensorflow/core/graph/graph.cc#L223-L229"
                }
            ],
            "source": {
                "advisory": "GHSA-vq36-27g6-p492",
                "discovery": "UNKNOWN"
            },
            "title": "Out of bounds read in Tensorflow",
            "x_legacyV4Record": {
                "CVE_data_meta": {
                    "ASSIGNER": "security-advisories@github.com",
                    "ID": "CVE-2022-23592",
                    "STATE": "PUBLIC",
                    "TITLE": "Out of bounds read in Tensorflow"
                },
                "affects": {
                    "vendor": {
                        "vendor_data": [
                            {
                                "product": {
                                    "product_data": [
                                        {
                                            "product_name": "tensorflow",
                                            "version": {
                                                "version_data": [
                                                    {
                                                        "version_value": ">= 2.7.0, < 2.8.0"
                                                    }
                                                ]
                                            }
                                        }
                                    ]
                                },
                                "vendor_name": "tensorflow"
                            }
                        ]
                    }
                },
                "data_format": "MITRE",
                "data_type": "CVE",
                "data_version": "4.0",
                "description": {
                    "description_data": [
                        {
                            "lang": "eng",
                            "value": "Tensorflow is an Open Source Machine Learning Framework. TensorFlow's type inference can cause a heap out of bounds read as the bounds checking is done in a `DCHECK` (which is a no-op during production). An attacker can control the `input_idx` variable such that `ix` would be larger than the number of values in `node_t.args`. The fix will be included in TensorFlow 2.8.0. This is the only affected version."
                        }
                    ]
                },
                "impact": {
                    "cvss": {
                        "attackComplexity": "LOW",
                        "attackVector": "NETWORK",
                        "availabilityImpact": "HIGH",
                        "baseScore": 8.1,
                        "baseSeverity": "HIGH",
                        "confidentialityImpact": "HIGH",
                        "integrityImpact": "NONE",
                        "privilegesRequired": "LOW",
                        "scope": "UNCHANGED",
                        "userInteraction": "NONE",
                        "vectorString": "CVSS:3.1/AV:N/AC:L/PR:L/UI:N/S:U/C:H/I:N/A:H",
                        "version": "3.1"
                    }
                },
                "problemtype": {
                    "problemtype_data": [
                        {
                            "description": [
                                {
                                    "lang": "eng",
                                    "value": "CWE-125: Out-of-bounds Read"
                                }
                            ]
                        }
                    ]
                },
                "references": {
                    "reference_data": [
                        {
                            "name": "https://github.com/tensorflow/tensorflow/security/advisories/GHSA-vq36-27g6-p492",
                            "refsource": "CONFIRM",
                            "url": "https://github.com/tensorflow/tensorflow/security/advisories/GHSA-vq36-27g6-p492"
                        },
                        {
                            "name": "https://github.com/tensorflow/tensorflow/commit/c99d98cd189839dcf51aee94e7437b54b31f8abd",
                            "refsource": "MISC",
                            "url": "https://github.com/tensorflow/tensorflow/commit/c99d98cd189839dcf51aee94e7437b54b31f8abd"
                        },
                        {
                            "name": "https://github.com/tensorflow/tensorflow/blob/274df9b02330b790aa8de1cee164b70f72b9b244/tensorflow/core/graph/graph.cc#L223-L229",
                            "refsource": "MISC",
                            "url": "https://github.com/tensorflow/tensorflow/blob/274df9b02330b790aa8de1cee164b70f72b9b244/tensorflow/core/graph/graph.cc#L223-L229"
                        }
                    ]
                },
                "source": {
                    "advisory": "GHSA-vq36-27g6-p492",
                    "discovery": "UNKNOWN"
                }
            }
        }
    },
    "cveMetadata": {
        "assignerOrgId": "a0819718-46f1-4df5-94e2-005712e83aaa",
        "assignerShortName": "GitHub_M",
        "cveId": "CVE-2022-23592",
        "datePublished": "2022-02-04T22:32:14",
        "dateReserved": "2022-01-19T00:00:00",
        "dateUpdated": "2022-02-04T22:32:14",
        "state": "PUBLISHED"
    },
    "dataType": "CVE_RECORD",
    "dataVersion": "5.0"
}